<?xml version="1.0" ?>
<!-- =================================================================================== -->
<!-- |    This document was autogenerated by xacro from model.sdf.xacro                | -->
<!-- |    EDITING THIS FILE BY HAND IS NOT RECOMMENDED                                 | -->
<!-- =================================================================================== -->
<sdf version="1.10">
  <model name="slash_4x4_ultimate">
    <static>false</static>
    <link name="base">
      <gravity>true</gravity>
      <inertial>
        <mass>5</mass>
        <inertia>
          <ixx>0.014612083333333336</ixx>
          <ixy>0</ixy>
          <ixz>0</ixz>
          <iyy>0.04378166666666666</iyy>
          <iyz>0</iyz>
          <izz>0.05831041666666666</izz>
        </inertia>
      </inertial>
      <collision name="base_collision">
        <geometry>
          <box>
            <size>0.324 0.187 0.01</size>
          </box>
        </geometry>
      </collision>
      <visual name="base_visual">
        <material>
          <diffuse>0 0 1 1</diffuse>
        </material>
        <geometry>
          <box>
            <size>0.324 0.187 0.01</size>
          </box>
        </geometry>
      </visual>
    </link>
    <joint name="counterweight_joint" type="fixed">
      <pose relative_to="base">0 0 -0.20210714285714287 0 0 0</pose>
      <parent>base</parent>
      <child>counterweight</child>
    </joint>
    <link name="counterweight">
      <!--<pose>0 0 -${tire_radius + chassis_height_offset + counterweight_com} 0 0 0</pose>-->
      <pose relative_to="counterweight_joint">0 0 0 0 0 0</pose>
      <gravity>true</gravity>
      <inertial>
        <mass>5.6</mass>
        <inertia>
          <ixx>0.012983716666666667</ixx>
          <ixy>0</ixy>
          <ixz>0</ixz>
          <iyy>0.049035466666666666</iyy>
          <iyz>0</iyz>
          <izz>0.061925850000000005</izz>
        </inertia>
      </inertial>
      <visual name="counterweight_visual">
        <material>
          <diffuse>0 0 0 1</diffuse>
        </material>
        <geometry>
          <box>
            <size>0.03 0.03 0.001</size>
          </box>
        </geometry>
      </visual>
    </link>
    <joint name="front_axle_center_joint" type="fixed">
      <pose relative_to="base">0.162 0 0 0 0 0</pose>
      <parent>base</parent>
      <child>front_axle_center</child>
    </joint>
    <link name="front_axle_center">
      <pose relative_to="front_axle_center_joint">0 0 0 0 0 0</pose>
    </link>
    <joint name="imu_joint" type="fixed">
      <pose relative_to="front_axle_center">-0.11 0 0 3.141592653589793 0 0</pose>
      <parent>front_axle_center</parent>
      <child>imu_link</child>
    </joint>
    <link name="imu_link">
      <pose relative_to="imu_joint">0 0 0 0 0 0</pose>
      <sensor name="imu_sensor" type="imu">
        <always_on>1</always_on>
        <update_rate>250</update_rate>
        <visualize>true</visualize>
        <topic>imu</topic>
      </sensor>
    </link>
    <joint name="left_steer_joint" type="revolute">
      <parent>base</parent>
      <child>left_steer_link</child>
      <pose relative_to="base">0.162 0.148 -0.02 0 0 0</pose>
      <axis>
        <xyz>0 0 1</xyz>
        <limit>
          <lower>-0.34055108028595943</lower>
          <upper>0.482655134332735</upper>
          <velocity>3.86124107466188</velocity>
          <effort>1e6</effort>
        </limit>
      </axis>
    </joint>
    <link name="left_steer_link">
      <pose relative_to="left_steer_joint">0 0 0 0 0 0</pose>
    </link>
    <joint name="right_steer_joint" type="revolute">
      <parent>base</parent>
      <child>right_steer_link</child>
      <pose relative_to="base">0.162 -0.148 -0.02 0 0 0</pose>
      <axis>
        <xyz>0 0 1</xyz>
        <limit>
          <lower>-0.482655134332735</lower>
          <upper>0.34055108028595943</upper>
          <velocity>3.86124107466188</velocity>
          <effort>1e6</effort>
        </limit>
      </axis>
    </joint>
    <link name="right_steer_link">
      <pose relative_to="right_steer_joint">0 0 0 0 0 0</pose>
    </link>
    <joint name="front_left_wheel_joint" type="revolute">
      <parent>left_steer_link</parent>
      <child>front_left_wheel</child>
      <pose relative_to="left_steer_joint">0 0 0 1.5707963267948966 0 0</pose>
      <axis>
        <xyz>0 0 -1</xyz>
        <limit>
          <lower>-1.79769e+308</lower>
          <upper>1.79769e+308</upper>
        </limit>
      </axis>
    </joint>
    <link name="front_left_wheel">
      <pose relative_to="front_left_wheel_joint">0 0 0 0 0 0</pose>
      <gravity>true</gravity>
      <inertial>
        <mass>0.15</mass>
        <inertia>
          <ixx>0.00025476171874999994</ixx>
          <ixy>0</ixy>
          <ixz>0</ixz>
          <iyy>0.00025476171874999994</iyy>
          <iyz>0</iyz>
          <izz>0.00046001718749999997</izz>
        </inertia>
      </inertial>
      <collision name="front_left_wheel_collision">
        <geometry>
          <cylinder>
            <radius>0.05475</radius>
            <length>0.0445</length>
          </cylinder>
        </geometry>
        <surface>
          <friction>
            <ode>
              <mu>1000</mu>
              <mu2>1000</mu2>
              <fdir1>1 0 0</fdir1>
              <slip1>0</slip1>
              <slip2>0</slip2>
            </ode>
          </friction>
          <contact>
            <ode>
              <min_depth>0.02</min_depth>
            </ode>
          </contact>
        </surface>
      </collision>
      <visual name="front_left_wheel_visual">
        <material>
          <diffuse>0 0 0 1</diffuse>
        </material>
        <geometry>
          <cylinder>
            <radius>0.05475</radius>
            <length>0.0445</length>
          </cylinder>
        </geometry>
      </visual>
    </link>
    <joint name="front_right_wheel_joint" type="revolute">
      <parent>right_steer_link</parent>
      <child>front_right_wheel</child>
      <pose relative_to="right_steer_joint">0 0 0 1.5707963267948966 0 0</pose>
      <axis>
        <xyz>0 0 -1</xyz>
        <limit>
          <lower>-1.79769e+308</lower>
          <upper>1.79769e+308</upper>
        </limit>
      </axis>
    </joint>
    <link name="front_right_wheel">
      <pose relative_to="front_right_wheel_joint">0 0 0 0 0 0</pose>
      <gravity>true</gravity>
      <inertial>
        <mass>0.15</mass>
        <inertia>
          <ixx>0.00025476171874999994</ixx>
          <ixy>0</ixy>
          <ixz>0</ixz>
          <iyy>0.00025476171874999994</iyy>
          <iyz>0</iyz>
          <izz>0.00046001718749999997</izz>
        </inertia>
      </inertial>
      <collision name="front_right_wheel_collision">
        <geometry>
          <cylinder>
            <radius>0.05475</radius>
            <length>0.0445</length>
          </cylinder>
        </geometry>
        <surface>
          <friction>
            <ode>
              <mu>1000</mu>
              <mu2>1000</mu2>
              <fdir1>1 0 0</fdir1>
              <slip1>0</slip1>
              <slip2>0</slip2>
            </ode>
          </friction>
          <contact>
            <ode>
              <min_depth>0.02</min_depth>
            </ode>
          </contact>
        </surface>
      </collision>
      <visual name="front_right_wheel_visual">
        <material>
          <diffuse>0 0 0 1</diffuse>
        </material>
        <geometry>
          <cylinder>
            <radius>0.05475</radius>
            <length>0.0445</length>
          </cylinder>
        </geometry>
      </visual>
    </link>
    <joint name="rear_left_wheel_joint" type="revolute">
      <parent>base</parent>
      <child>rear_left_wheel</child>
      <pose relative_to="base">-0.162 0.148 -0.02 1.5707963267948966 0 0</pose>
      <axis>
        <xyz>0 0 -1</xyz>
        <limit>
          <lower>-1.79769e+308</lower>
          <upper>1.79769e+308</upper>
        </limit>
      </axis>
    </joint>
    <link name="rear_left_wheel">
      <pose relative_to="rear_left_wheel_joint">0 0 0 0 0 0</pose>
      <gravity>true</gravity>
      <inertial>
        <mass>0.15</mass>
        <inertia>
          <ixx>0.00025476171874999994</ixx>
          <ixy>0</ixy>
          <ixz>0</ixz>
          <iyy>0.00025476171874999994</iyy>
          <iyz>0</iyz>
          <izz>0.00046001718749999997</izz>
        </inertia>
      </inertial>
      <collision name="rear_left_wheel_collision">
        <geometry>
          <cylinder>
            <radius>0.05475</radius>
            <length>0.0445</length>
          </cylinder>
        </geometry>
        <surface>
          <friction>
            <ode>
              <mu>1000</mu>
              <mu2>1000</mu2>
              <fdir1>1 0 0</fdir1>
              <slip1>0</slip1>
              <slip2>0</slip2>
            </ode>
          </friction>
          <contact>
            <ode>
              <min_depth>0.02</min_depth>
            </ode>
          </contact>
        </surface>
      </collision>
      <visual name="rear_left_wheel_visual">
        <material>
          <diffuse>0 0 0 1</diffuse>
        </material>
        <geometry>
          <cylinder>
            <radius>0.05475</radius>
            <length>0.0445</length>
          </cylinder>
        </geometry>
      </visual>
    </link>
    <joint name="rear_right_wheel_joint" type="revolute">
      <parent>base</parent>
      <child>rear_right_wheel</child>
      <pose relative_to="base">-0.162 -0.148 -0.02 1.5707963267948966 0 0</pose>
      <axis>
        <xyz>0 0 -1</xyz>
        <limit>
          <lower>-1.79769e+308</lower>
          <upper>1.79769e+308</upper>
        </limit>
      </axis>
    </joint>
    <link name="rear_right_wheel">
      <pose relative_to="rear_right_wheel_joint">0 0 0 0 0 0</pose>
      <gravity>true</gravity>
      <inertial>
        <mass>0.15</mass>
        <inertia>
          <ixx>0.00025476171874999994</ixx>
          <ixy>0</ixy>
          <ixz>0</ixz>
          <iyy>0.00025476171874999994</iyy>
          <iyz>0</iyz>
          <izz>0.00046001718749999997</izz>
        </inertia>
      </inertial>
      <collision name="rear_right_wheel_collision">
        <geometry>
          <cylinder>
            <radius>0.05475</radius>
            <length>0.0445</length>
          </cylinder>
        </geometry>
        <surface>
          <friction>
            <ode>
              <mu>1000</mu>
              <mu2>1000</mu2>
              <fdir1>1 0 0</fdir1>
              <slip1>0</slip1>
              <slip2>0</slip2>
            </ode>
          </friction>
          <contact>
            <ode>
              <min_depth>0.02</min_depth>
            </ode>
          </contact>
        </surface>
      </collision>
      <visual name="rear_right_wheel_visual">
        <material>
          <diffuse>0 0 0 1</diffuse>
        </material>
        <geometry>
          <cylinder>
            <radius>0.05475</radius>
            <length>0.0445</length>
          </cylinder>
        </geometry>
      </visual>
    </link>
    <!-- Laser -->
    <joint name="base_to_laser_rviz" type="fixed">
      <parent>base</parent>
      <child>sputnik/rplidar_a3/lidar_link/gpu_lidar</child>
      <pose relative_to="base">0.1144 0 0.1 0 0 0.0</pose>
    </joint>
    <link name="sputnik/rplidar_a3/lidar_link/gpu_lidar">
      <pose relative_to="base_to_laser_rviz">0 0 0 0 0 0</pose>
    </link>
    <joint name="base_to_laser_sensor" type="fixed">
      <parent>base</parent>
      <child>rplidar_a3::lidar_link</child>
      <pose relative_to="base">0.1144 0 0.1 0 0 0.0</pose>
    </joint>
    <include>
      <uri>model://rplidar_a3</uri>
      <pose relative_to="base_to_laser_sensor">0 0 0 0 0 0</pose>
    </include>
    <!-- Plugins> -->
    <plugin filename="gz-sim-joint-position-controller-system" name="gz::sim::systems::JointPositionController">
      <joint_name>left_steer_joint</joint_name>
      <cmd_max>3.86124107466188</cmd_max>
      <use_velocity_commands>true</use_velocity_commands>
    </plugin>
    <plugin filename="gz-sim-joint-position-controller-system" name="gz::sim::systems::JointPositionController">
      <joint_name>right_steer_joint</joint_name>
      <cmd_max>3.86124107466188</cmd_max>
      <use_velocity_commands>true</use_velocity_commands>
    </plugin>
    <plugin filename="gz-sim-joint-controller-system" name="gz::sim::systems::JointController">
      <joint_name>front_left_wheel_joint</joint_name>
      <use_force_commands>false</use_force_commands>
      <topic>/model/sputnik/joint/front_left_wheel_joint/cmd_vel</topic>
    </plugin>
    <plugin filename="gz-sim-joint-controller-system" name="gz::sim::systems::JointController">
      <joint_name>front_right_wheel_joint</joint_name>
      <use_force_commands>false</use_force_commands>
      <topic>/model/sputnik/joint/front_right_wheel_joint/cmd_vel</topic>
    </plugin>
    <plugin filename="gz-sim-joint-controller-system" name="gz::sim::systems::JointController">
      <joint_name>rear_left_wheel_joint</joint_name>
      <use_force_commands>false</use_force_commands>
      <topic>/model/sputnik/joint/rear_left_wheel_joint/cmd_vel</topic>
    </plugin>
    <plugin filename="gz-sim-joint-controller-system" name="gz::sim::systems::JointController">
      <joint_name>rear_right_wheel_joint</joint_name>
      <use_force_commands>false</use_force_commands>
      <topic>/model/sputnik/joint/rear_right_wheel_joint/cmd_vel</topic>
    </plugin>
    <plugin filename="gz-sim-joint-state-publisher-system" name="gz::sim::systems::JointStatePublisher">
      <topic>/model/sputnik/joint_state</topic>
      <joint_name>left_steer_joint</joint_name>
      <joint_name>right_steer_joint</joint_name>
      <joint_name>front_left_wheel_joint</joint_name>
      <joint_name>front_right_wheel_joint</joint_name>
      <joint_name>rear_left_wheel_joint</joint_name>
      <joint_name>rear_right_wheel_joint</joint_name>
    </plugin>
    <!--<plugin
      filename="gz-sim-pose-publisher-system"
      name="gz::sim::systems::PosePublisher">
      <publish_model_pose>true</publish_model_pose>
      <static_publisher>true</static_publisher>
      <use_pose_vector_msg>true</use_pose_vector_msg>
      <static_update_frequency>-1</static_update_frequency>
    </plugin>-->
    <plugin filename="gz-sim-odometry-publisher-system" name="gz::sim::systems::OdometryPublisher">
      <odom_frame>world/ground_plane</odom_frame>
      <!--<robot_base_frame>sputnik/rplidar_a3/lidar_link/gpu_lidar</robot_base_frame>-->
      <robot_base_frame>sputnik/base</robot_base_frame>
      <odom_publish_frequency>500</odom_publish_frequency>
    </plugin>
  </model>
</sdf>
