<?xml version="1.0" ?>
<!-- =================================================================================== -->
<!-- |    This document was autogenerated by xacro from model.sdf.xacro                | -->
<!-- |    EDITING THIS FILE BY HAND IS NOT RECOMMENDED                                 | -->
<!-- =================================================================================== -->
<sdf version="1.10">
  <model name="slash_4x4_ultimate">
    <static>false</static>
    <link name="base">
      <gravity>true</gravity>
      <!--<xacro:solid_cuboid_inertial
        width="${wheelbase}" depth="${2*(half_track - tire_width - 0.01)}" height="${chassis_depth}" mass="${chassis_mass}"/>
      <collision name="base_collision">
        <geometry>
          <box>
            <size>${wheelbase} ${2*(half_track - tire_width - 0.01)} ${chassis_depth}</size>
          </box>
        </geometry>
      </collision>-->
      <visual name="base_visual">
        <material>
          <diffuse>0 0 1 1</diffuse>
        </material>
        <geometry>
          <box>
            <size>0.324 0.187 0.01</size>
          </box>
        </geometry>
      </visual>
    </link>
    <joint name="front_axle_center_joint" type="fixed">
      <pose relative_to="base">0.162 0 0 0 0 0</pose>
      <parent>base</parent>
      <child>front_axle_center</child>
    </joint>
    <link name="front_axle_center">
      <pose relative_to="front_axle_center_joint">0 0 0 0 0 0</pose>
    </link>
    <joint name="imu_joint" type="fixed">
      <pose relative_to="front_axle_center">-0.11 0 0 3.141592653589793 0 0</pose>
      <parent>front_axle_center</parent>
      <child>imu_link</child>
    </joint>
    <link name="imu_link">
      <pose relative_to="imu_joint">0 0 0 0 0 0</pose>
    </link>
    <joint name="left_steer_joint" type="revolute">
      <parent>base</parent>
      <child>left_steer_link</child>
      <pose relative_to="base">0.162 0.148 -0.02 0 0 0</pose>
      <axis>
        <xyz>0 0 1</xyz>
        <limit>
          <lower>-0.29560744145545503</lower>
          <upper>0.3992510660039466</upper>
          <velocity>3.194008528031573</velocity>
          <effort>1e6</effort>
        </limit>
      </axis>
    </joint>
    <link name="left_steer_link">
      <pose relative_to="left_steer_joint">0 0 0 0 0 0</pose>
    </link>
    <joint name="right_steer_joint" type="revolute">
      <parent>base</parent>
      <child>right_steer_link</child>
      <pose relative_to="base">0.162 -0.148 -0.02 0 0 0</pose>
      <axis>
        <xyz>0 0 1</xyz>
        <limit>
          <lower>-0.3992510660039466</lower>
          <upper>0.29560744145545503</upper>
          <velocity>3.194008528031573</velocity>
          <effort>1e6</effort>
        </limit>
      </axis>
    </joint>
    <link name="right_steer_link">
      <pose relative_to="right_steer_joint">0 0 0 0 0 0</pose>
    </link>
    <joint name="front_left_wheel_joint" type="revolute">
      <parent>left_steer_link</parent>
      <child>front_left_wheel</child>
      <pose relative_to="left_steer_joint">0 0 0 1.5707963267948966 0 0</pose>
      <axis>
        <xyz>0 0 -1</xyz>
        <limit>
          <lower>-1.79769e+308</lower>
          <upper>1.79769e+308</upper>
        </limit>
      </axis>
    </joint>
    <link name="front_left_wheel">
      <pose relative_to="front_left_wheel_joint">0 0 0 0 0 0</pose>
      <visual name="front_left_wheel_visual">
        <material>
          <diffuse>0 0 0 1</diffuse>
        </material>
        <geometry>
          <cylinder>
            <radius>0.05475</radius>
            <length>0.0445</length>
          </cylinder>
        </geometry>
      </visual>
    </link>
    <joint name="front_right_wheel_joint" type="revolute">
      <parent>right_steer_link</parent>
      <child>front_right_wheel</child>
      <pose relative_to="right_steer_joint">0 0 0 1.5707963267948966 0 0</pose>
      <axis>
        <xyz>0 0 -1</xyz>
        <limit>
          <lower>-1.79769e+308</lower>
          <upper>1.79769e+308</upper>
        </limit>
      </axis>
    </joint>
    <link name="front_right_wheel">
      <pose relative_to="front_right_wheel_joint">0 0 0 0 0 0</pose>
      <visual name="front_right_wheel_visual">
        <material>
          <diffuse>0 0 0 1</diffuse>
        </material>
        <geometry>
          <cylinder>
            <radius>0.05475</radius>
            <length>0.0445</length>
          </cylinder>
        </geometry>
      </visual>
    </link>
    <joint name="rear_left_wheel_joint" type="revolute">
      <parent>base</parent>
      <child>rear_left_wheel</child>
      <pose relative_to="base">-0.162 0.148 -0.02 1.5707963267948966 0 0</pose>
      <axis>
        <xyz>0 0 -1</xyz>
        <limit>
          <lower>-1.79769e+308</lower>
          <upper>1.79769e+308</upper>
        </limit>
      </axis>
    </joint>
    <link name="rear_left_wheel">
      <pose relative_to="rear_left_wheel_joint">0 0 0 0 0 0</pose>
      <visual name="rear_left_wheel_visual">
        <material>
          <diffuse>0 0 0 1</diffuse>
        </material>
        <geometry>
          <cylinder>
            <radius>0.05475</radius>
            <length>0.0445</length>
          </cylinder>
        </geometry>
      </visual>
    </link>
    <joint name="rear_right_wheel_joint" type="revolute">
      <parent>base</parent>
      <child>rear_right_wheel</child>
      <pose relative_to="base">-0.162 -0.148 -0.02 1.5707963267948966 0 0</pose>
      <axis>
        <xyz>0 0 -1</xyz>
        <limit>
          <lower>-1.79769e+308</lower>
          <upper>1.79769e+308</upper>
        </limit>
      </axis>
    </joint>
    <link name="rear_right_wheel">
      <pose relative_to="rear_right_wheel_joint">0 0 0 0 0 0</pose>
      <gravity>true</gravity>
      <visual name="rear_right_wheel_visual">
        <material>
          <diffuse>0 0 0 1</diffuse>
        </material>
        <geometry>
          <cylinder>
            <radius>0.05475</radius>
            <length>0.0445</length>
          </cylinder>
        </geometry>
      </visual>
    </link>
    <!-- Laser -->
    <joint name="base_to_laser_rviz" type="fixed">
      <parent>base</parent>
      <child>sputnik/rplidar_a3/lidar_link/gpu_lidar</child>
      <pose relative_to="base">0.1144 0 0.1 0 0 0</pose>
    </joint>
    <link name="sputnik/rplidar_a3/lidar_link/gpu_lidar">
      <pose relative_to="base_to_laser_rviz">0 0 0 0 0 0</pose>
    </link>
  </model>
</sdf>
