<?xml version="1.0" ?>
<!-- =================================================================================== -->
<!-- |    This document was autogenerated by xacro from slash_4x4_ultimate.urdf.xacro  | -->
<!-- |    EDITING THIS FILE BY HAND IS NOT RECOMMENDED                                 | -->
<!-- =================================================================================== -->
<robot name="slash_4x4_ultimate">
  <link name="base">
    <visual>
      <origin rpy="0 0 0" xyz="0 0 0"/>
      <geometry>
        <box size="0.324 0.187 0.01"/>
      </geometry>
    </visual>
    <!--    <collision>
      <origin xyz="0 0 0" rpy="0 0 0" />
      <geometry>
        <box size="${wheelbase} ${2*half_track - tire_radius} ${chassis_depth}" />
      </geometry>
    </collision>-->
    <!--    <xacro:solid_cuboid_inertial
      width="${wheelbase}" depth="${2*(half_track - tire_width - 0.01)}" height="${chassis_depth}" mass="${chassis_mass}">
      <origin/>
    </xacro:solid_cuboid_inertial>-->
  </link>
  <gazebo reference="base">
    <visual name="visual">
      <material>
        <diffuse>0 0 1 1</diffuse>
      </material>
    </visual>
    <gravity>true</gravity>
  </gazebo>
  <link name="counterweight">
    <visual>
      <origin rpy="0 0 0" xyz="0 0 0"/>
      <geometry>
        <box size="0.324 0.1665 0.01"/>
      </geometry>
    </visual>
    <inertial>
      <origin/>
      <mass value="2.28"/>
      <inertia ixx="0.005286227500000001" ixy="0" ixz="0" iyy="0.01996444" iyz="0" izz="0.025212667500000004"/>
    </inertial>
  </link>
  <gazebo reference="counterweight">
    <visual name="visual">
      <material>
        <diffuse>0 0 0 1</diffuse>
      </material>
    </visual>
    <gravity>true</gravity>
  </gazebo>
  <joint name="counterweight_joint" type="fixed">
    <parent link="base"/>
    <child link="counterweight"/>
    <origin xyz="0 0 -0.14423684210526316"/>
  </joint>
  <link name="front_left_bar">
    <inertial>
      3311.315862   Duration: 2.442862 / 7.601000      
      
      <mass value="0.001"/>
      <inertia ixx="0.001" ixy="0" ixz="0" iyy="0.001" iyz="0" izz="0.001"/>
    </inertial>
  </link>
  <gazebo reference="front_left_bar">
    <visual name="visual">
      <material>
        <diffuse>0 1 0 1</diffuse>
      </material>
    </visual>
    <gravity>false</gravity>
  </gazebo>
  <joint name="front_left_bar_joint" type="revolute">
    <limit effort="100" lower="-0.3992510660039466" upper="0.3992510660039466" velocity="10"/>
    <axis xyz="0 0 1"/>
    <parent link="base"/>
    <child link="front_left_bar"/>
    <origin rpy="0 0 0.42848622704577766" xyz="0.162 0.148 -0.02"/>
    <!--<limit lower="${-inside_max_steer_ang}" upper="${inside_max_steer_ang}"
           effort="${servo_stall_torque}" velocity="${servo_no_load_speed}"/>-->
  </joint>
  <link name="front_right_bar">
    <inertial>
      3311.315862   Duration: 2.442862 / 7.601000      
      
      <mass value="0.001"/>
      <inertia ixx="0.001" ixy="0" ixz="0" iyy="0.001" iyz="0" izz="0.001"/>
    </inertial>
  </link>
  <gazebo reference="front_right_bar">
    <visual name="visual">
      <material>
        <diffuse>0 1 0 1</diffuse>
      </material>
    </visual>
    <gravity>false</gravity>
  </gazebo>
  <joint name="front_right_bar_joint" type="revolute">
    <limit effort="100" lower="-0.3992510660039466" upper="0.3992510660039466" velocity="10"/>
    <axis xyz="0 0 1"/>
    <parent link="base"/>
    <child link="front_right_bar"/>
    <origin rpy="0 0 -0.42848622704577766" xyz="0.162 -0.148 -0.02"/>
    <!--<limit lower="${-inside_max_steer_ang}" upper="${inside_max_steer_ang}"
           effort="${servo_stall_torque}" velocity="${servo_no_load_speed}"/>-->
  </joint>
  <gazebo>
    <link name="ackermann_bar">
      <gravity>false</gravity>
      <pose>0.03711641143462856 0 -0.02 0 0 0</pose>
      <inertial>
        <inertia>
          <ixx>0.001</ixx>
          <ixy>0</ixy>
          <ixz>0</ixz>
          <iyy>0.001</iyy>
          <iyz>0</iyz>
          <izz>0.001</izz>
        </inertia>
        <mass>0.001</mass>
      </inertial>
      <!--<visual>
        <geometry>
          <box>
            <size>${bar_thickness} ${ackermann_bar_length} ${bar_thickness}</size>
          </box>
        </geometry>
      </visual>-->
    </link>
  </gazebo>
  <gazebo>
    <joint name="left_ackermann_bar_joint" type="revolute">
      <parent>front_left_bar</parent>
      <child>ackermann_bar</child>
      <pose>0 0.09095441016149701 0 0 0 0</pose>
      <axis>
        <xyz>0 0 1</xyz>
      </axis>
    </joint>
  </gazebo>
  <gazebo>
    <joint name="right_ackermann_bar_joint" type="revolute">
      <parent>front_right_bar</parent>
      <child>ackermann_bar</child>
      <pose>0 -0.09095441016149701 0 0 0 0</pose>
      <axis>
        <xyz>0 0 1</xyz>
      </axis>
    </joint>
  </gazebo>
  <link name="front_left_wheel">
    <visual>
      <origin rpy="0 0 0" xyz="0 0 0"/>
      <geometry>
        <cylinder length="0.0445" radius="0.05475"/>
      </geometry>
    </visual>
    <collision>
      <origin rpy="0 0 0" xyz="0 0 0"/>
      <geometry>
        <cylinder length="0.0445" radius="0.05475"/>
      </geometry>
    </collision>
    <inertial>
      <mass value="0.15"/>
      <inertia ixx="0.00025476171874999994" ixy="0" ixz="0" iyy="0.00025476171874999994" iyz="0" izz="0.00046001718749999997"/>
    </inertial>
  </link>
  <gazebo reference="front_left_wheel">
    <collision>
      <surface>
        <friction>
          <ode>
            <mu>1000</mu>
            <mu2>1000</mu2>
            <fdir1>1 0 0</fdir1>
            <slip1>0</slip1>
            <slip2>0</slip2>
          </ode>
        </friction>
        <contact>
          <ode>
            <min_depth>0.02</min_depth>
          </ode>
        </contact>
      </surface>
    </collision>
    <visual name="visual">
      <material>
        <diffuse>0 0 0 1</diffuse>
      </material>
    </visual>
    <gravity>true</gravity>
  </gazebo>
  <joint name="front_left_wheel_joint" type="continuous">
    <axis xyz="0 0 -1"/>
    <parent link="front_left_bar"/>
    <child link="front_left_wheel"/>
    <origin rpy="1.5707963267948966 0 -0.42848622704577766" xyz="0 0 0"/>
    <limit effort="5.12766" velocity="244.8696"/>
  </joint>
  <link name="front_right_wheel">
    <visual>
      <origin rpy="0 0 0" xyz="0 0 0"/>
      <geometry>
        <cylinder length="0.0445" radius="0.05475"/>
      </geometry>
    </visual>
    <collision>
      <origin rpy="0 0 0" xyz="0 0 0"/>
      <geometry>
        <cylinder length="0.0445" radius="0.05475"/>
      </geometry>
    </collision>
    <inertial>
      <mass value="0.15"/>
      <inertia ixx="0.00025476171874999994" ixy="0" ixz="0" iyy="0.00025476171874999994" iyz="0" izz="0.00046001718749999997"/>
    </inertial>
  </link>
  <gazebo reference="front_right_wheel">
    <collision>
      <surface>
        <friction>
          <ode>
            <mu>1000</mu>
            <mu2>1000</mu2>
            <fdir1>1 0 0</fdir1>
            <slip1>0</slip1>
            <slip2>0</slip2>
          </ode>
        </friction>
        <contact>
          <ode>
            <min_depth>0.02</min_depth>
          </ode>
        </contact>
      </surface>
    </collision>
    <visual name="visual">
      <material>
        <diffuse>0 0 0 1</diffuse>
      </material>
    </visual>
    <gravity>true</gravity>
  </gazebo>
  <joint name="front_right_wheel_joint" type="continuous">
    <axis xyz="0 0 -1"/>
    <parent link="front_right_bar"/>
    <child link="front_right_wheel"/>
    <origin rpy="1.5707963267948966 0 0.42848622704577766" xyz="0 0 0"/>
    <limit effort="5.12766" velocity="244.8696"/>
  </joint>
  <link name="rear_left_wheel">
    <visual>
      <origin rpy="0 0 0" xyz="0 0 0"/>
      <geometry>
        <cylinder length="0.0445" radius="0.05475"/>
      </geometry>
    </visual>
    <collision>
      <origin rpy="0 0 0" xyz="0 0 0"/>
      <geometry>
        <cylinder length="0.0445" radius="0.05475"/>
      </geometry>
    </collision>
    <inertial>
      <mass value="0.15"/>
      <inertia ixx="0.00025476171874999994" ixy="0" ixz="0" iyy="0.00025476171874999994" iyz="0" izz="0.00046001718749999997"/>
    </inertial>
  </link>
  <gazebo reference="rear_left_wheel">
    <collision>
      <surface>
        <friction>
          <ode>
            <mu>1000</mu>
            <mu2>1000</mu2>
            <fdir1>1 0 0</fdir1>
            <slip1>0</slip1>
            <slip2>0</slip2>
          </ode>
        </friction>
        <contact>
          <ode>
            <min_depth>0.02</min_depth>
          </ode>
        </contact>
      </surface>
    </collision>
    <visual name="visual">
      <material>
        <diffuse>0 0 0 1</diffuse>
      </material>
    </visual>
    <gravity>true</gravity>
  </gazebo>
  <joint name="rear_left_wheel_joint" type="continuous">
    <axis xyz="0 0 -1 "/>
    <parent link="base"/>
    <child link="rear_left_wheel"/>
    <origin rpy="1.5707963267948966 0 0" xyz="-0.162 0.148 -0.02"/>
    <limit effort="5.12766" velocity="244.8696"/>
  </joint>
  <link name="rear_right_wheel">
    <visual>
      <origin rpy="0 0 0" xyz="0 0 0"/>
      <geometry>
        <cylinder length="0.0445" radius="0.05475"/>
      </geometry>
    </visual>
    <collision>
      <origin rpy="0 0 0" xyz="0 0 0"/>
      <geometry>
        <cylinder length="0.0445" radius="0.05475"/>
      </geometry>
    </collision>
    <inertial>
      <mass value="0.15"/>
      <inertia ixx="0.00025476171874999994" ixy="0" ixz="0" iyy="0.00025476171874999994" iyz="0" izz="0.00046001718749999997"/>
    </inertial>
  </link>
  <gazebo reference="rear_right_wheel">
    <collision>
      <surface>
        <friction>
          <ode>
            <mu>1000</mu>
            <mu2>1000</mu2>
            <fdir1>1 0 0</fdir1>
            <slip1>0</slip1>
            <slip2>0</slip2>
          </ode>
        </friction>
        <contact>
          <ode>
            <min_depth>0.02</min_depth>
          </ode>
        </contact>
      </surface>
    </collision>
    <visual name="visual">
      <material>
        <diffuse>0 0 0 1</diffuse>
      </material>
    </visual>
    <gravity>true</gravity>
  </gazebo>
  <joint name="rear_right_wheel_joint" type="continuous">
    <axis xyz="0 0 -1"/>
    <parent link="base"/>
    <child link="rear_right_wheel"/>
    <origin rpy="1.5707963267948966 0 0" xyz="-0.162 -0.148 -0.02"/>
    <limit effort="5.12766" velocity="244.8696"/>
  </joint>
  <!-- Laser -->
  <gazebo>
    <include>
      <uri>model://rplidar_a3</uri>
      <pose>0.1144 0 0.1 0 0 -3.141592653589793</pose>
    </include>
    <joint name="base_to_laser" type="fixed">
      <child>rplidar_a3::lidar_link</child>
      <parent>base</parent>
    </joint>
  </gazebo>
  <gazebo>
    <static>false</static>
    <plugin filename="gz-sim-ackermann-steering-system" name="gz::sim::systems::AckermannSteering">
      <steering_only>false</steering_only>
      <use_actuator_msg>false</use_actuator_msg>
      <left_joint>front_left_wheel_joint</left_joint>
      <left_joint>rear_left_wheel_joint</left_joint>
      <right_joint>front_right_wheel_joint</right_joint>
      <right_joint>rear_right_wheel_joint</right_joint>
      <left_steering_joint>front_left_bar_joint</left_steering_joint>
      <right_steering_joint>front_right_bar_joint</right_steering_joint>
      <wheel_separation>0.296</wheel_separation>
      <kingpin_width>0.296</kingpin_width>
      <wheelbase>0.324</wheelbase>
      <steering_limit>0.3992510660039466</steering_limit>
      <wheel_radius>0.05475</wheel_radius>
      <odom_publish_frequency>50</odom_publish_frequency>
      <min_velocity>0</min_velocity>
      <max_velocity>11</max_velocity>
      <min_acceleration>0</min_acceleration>
      <max_acceleration>50</max_acceleration>
      <min_jerk>0</min_jerk>
      <max_jerk>100</max_jerk>
    </plugin>
    <plugin filename="gz-sim-joint-state-publisher-system" name="gz::sim::systems::JointStatePublisher">
    </plugin>
    <plugin filename="gz-sim-pose-publisher-system" name="gz::sim::systems::PosePublisher">
      <publish_link_pose>true</publish_link_pose>
      <publish_model_pose>true</publish_model_pose>
      <use_pose_vector_msg>true</use_pose_vector_msg>
      <static_update_frequency>-1</static_update_frequency>
    </plugin>
  </gazebo>
</robot>
